Workbook
Name Bijlage_02_x: #REF!
Name Bijlage_06_x: #REF!
Name Bijlage_13_tabel_6.1_phi: #REF!
Name Bijlage_13_Tabel_6.2_S: #REF!
Name Bijlage_13_Tabel_6.3_POP: #REF!
Name phi: #REF!
Name T_c_eff: Parametertabel!$K$5:$K$68
Name T_cu_low: Parametertabel!$Q$5:$Q$68
Name T_cu_mean: Parametertabel!$R$5:$R$68
Name T_drained_undrained: Parametertabel!$F$5:$F$68
Name T_gamma_dry_high: Parametertabel!$H$5:$H$68
Name T_gamma_dry_low: Parametertabel!$G$5:$G$68
Name T_gamma_wet_high: Parametertabel!$J$5:$J$68
Name T_gamma_wet_low: Parametertabel!$I$5:$I$68
Name T_m_low: Parametertabel!$W$5:$W$68
Name T_m_mean: Parametertabel!$X$5:$X$68
Name T_phi_low: Parametertabel!$N$5:$N$68
Name T_phi_mean: Parametertabel!$O$5:$O$68
Name T_POP_low: Parametertabel!$Y$5:$Y$68
Name T_POP_mean: Parametertabel!$Z$5:$Z$68
Name T_psi: Parametertabel!$P$5:$P$68
Name T_S_low: Parametertabel!$U$5:$U$68
Name T_S_mean: Parametertabel!$V$5:$V$68
Name T_shansep_param: Parametertabel!$T$5:$T$68
Name T_Vs_high: Parametertabel!$AB$5
Name T_Vs_low: Parametertabel!$AA$5:$AA$68
Name TABEL: Parametertabel!$A$5:$AB$68
Name Tabel_expertgroep: #REF!
Name ucs: #REF!

Sheet Parametertabel
A1: Waar Bijlage 6 een keuze geeft tussen gedraineerd en ongedraineerd is een splitsing gemaakt in z en k. | D1: Voor alle keuzen geldt dat de IBs op basis van het beschikbare grondonderzoek moeten aantonen dat de keuze correct is. | G1: Eis D.10 verwijst naar Tabel 2b van NEN 9997:2017. Getoetst aan Tabel 2b-1 en 2b-2 van Ontw. NEN 9997:2022; volumegewichten zijn identiek aan Tabel 2b van NEN 9997:2017. | R1: Geen waarden beschikbaar. | S1: Dit is een check of het gaat om een zware klei, waar de SHANSEP parameters niet mogen worden gebruikt. | U1: De waarde voor keileem in de tabel 6.2 wordt niet gebruikt. | V1: De waarde voor keileem in de tabel 6.2 wordt niet gebruikt.
A2: SOS Code | B2: SOS Omschrijving | C2: NEN Omschrijving | D2: ="Toelichting bij keuze voor "&C2 -> Toelichting bij keuze voor NEN Omschrijving | E2: Indicatieve conuswaarde volgens Tabel 2b, niet voor ontwerp | F2: Gedraineerd / Ongedraineerd (G/D) | G2: γd (ondergrens) | H2: γd (bovengrens) | I2: γn (ondergrens) | J2: γn (bovengrens) | K2: c' (eff. coh.) | L2: omschrijving tbv Bijlage 13 tabel 6.1 | M2: ="Toelichting bij keuze voor "&L2 -> Toelichting bij keuze voor omschrijving tbv Bijlage 13 tabel 6.1 | N2: φ'(ondergrens) | O2: φ'(verwachtings-waarde) | P2: Ψ | Q2: cu (ondergrens) | R2: cu (verwachtingswaarde) | S2: klei met volgew > 17 kN/m3? | T2: SHANSEP parameters? | U2: S (ondergrens) | V2: S (verwachtings-waarde) | W2: m (ondergrens) | X2: m (verwachtings-waarde) | Y2: POP (ondergrens) | Z2: POP (verwachtings-waarde) | AA2: Vs(ondergrens) | AB2: Vs(bovengrens)
E3: [MPa] | G3: [kN/m3] | H3: [kN/m3] | I3: [kN/m3] | J3: [kN/m3] | K3: [kN/m2] | N3: [o] | O3: [o] | P3: [o] | Q3: [kN/m2] | R3: [kN/m2] | U3: [-] | V3: [-] | W3: [-] | X3: [-] | Y3: [kN/m2] | Z3: [kN/m2] | AA3: [m/s] | AB3: [m/s]
A4: Bijlage 06 | B4: Bijlage 06 | C4: Bijlage 02 | E4: Bijlage 02 (NEN 9997:2022) | F4: Bijlage 06 | G4: Bijlage 02 (NEN 9997:2022) | H4: Bijlage 02 (NEN 9997:2022) | I4: Bijlage 02 (NEN 9997:2022) | J4: Bijlage 02 (NEN 9997:2022) | K4: Bijlage 13 | N4: Bijlage 13 - tabel 6.1 | O4: Bijlage 13 - tabel 6.1 | P4: Bijlage 13 | Q4: Memo Deltares "Minimum waarde voor de ongedraineerde sterkte voor LNA" | R4: Memo Deltares "Minimum waarde voor de ongedraineerde sterkte voor LNA" | S4: Eisen D.15, D.17, D.19 in Bijlage 13. Aanvullend gelden deze eisen ook voor silt. | U4: Tabel expertgroep en Bijlage 13 - tabel 6.2 | V4: Tabel expertgroep en Bijlage 13 - tabel 6.2 | W4: Tabel expertgroep | X4: Tabel expertgroep | Y4: Tabel expertgroep en Bijlage 13 - tabel 6.3 | Z4: Tabel expertgroep en Bijlage 13 - tabel 6.3 | AA4: Bijlage 24 | AB4: Bijlage 24
A5: H_Mg_zm | B5: Matig fijn tot zeer grof getijdengeul­zand | C5: zand, siltig/kleiig, los | E5: 8 | F5: G | G5: 18 | H5: 19 | I5: 20 | J5: 21 | K5: 0 | L5: Matig gesorteerd matig hoekig kwartszand | M5: Deze eenheid komt vaak voor zonder kleilagen. In dat geval is keus "Matig gesorteerd matig hoekig kwartszand". IB dient deze keus te onderbouwen. | N5: 32.4 | O5: 34 | P5: 0 | Q5: - | R5: - | S5: nee | T5: nee, gedraineerd | U5: - | V5: - | W5: - | X5: - | Y5: - | Z5: - | AA5: 103 | AB5: 103
A6: H_Mg_zf | B6: Uiterst fijn tot matig fijn getijdengeul­zand | C6: zand, siltig/kleiig, los | E6: 8 | F6: G | G6: 18 | H6: 19 | I6: 20 | J6: 21 | K6: 0 | L6: Zand met kleilaagjes (getijdenafzettingen) | N6: 29.9 | O6: 32 | P6: 0 | Q6: - | R6: - | S6: nee | T6: nee, gedraineerd | U6: - | V6: - | W6: - | X6: - | Y6: - | Z6: - | AA6: 103 | AB6: 103
A7: H_Mg_zk | B7: Uiterst fijn tot matig fijn getijdengeul­zand met dunne klei- en silt laagjes | C7: zand, siltig/kleiig, los | E7: 8 | F7: G | G7: 18 | H7: 19 | I7: 20 | J7: 21 | K7: 0 | L7: Zand met kleilaagjes (getijdenafzettingen) | N7: 29.9 | O7: 32 | P7: 0 | Q7: - | R7: - | S7: nee | T7: nee, gedraineerd | U7: - | V7: - | W7: - | X7: - | Y7: - | Z7: - | AA7: 103 | AB7: 103
A8: H_Mp_zf | B8: Zandige getijdenplaat-afzettingen | C8: zand, los | E8: 5 | F8: G | G8: 17 | H8: 18 | I8: 19 | J8: 20 | K8: 0 | L8: Zand met kleilaagjes (getijdenafzettingen) | N8: 29.9 | O8: 32 | P8: 0 | Q8: - | R8: - | S8: nee | T8: nee, gedraineerd | U8: - | V8: - | W8: - | X8: - | Y8: - | Z8: - | AA8: 103 | AB8: 103
A9: H_Mr_kz_z | B9: Getijdenrest-geulopvulling | C9: zand, siltig/kleiig, los | E9: 8 | F9: G | G9: 18 | H9: 19 | I9: 20 | J9: 21 | K9: 0 | L9: Zand met kleilaagjes (getijdenafzettingen) | N9: 29.9 | O9: 32 | P9: 0 | Q9: - | R9: - | S9: nee | T9: nee, gedraineerd | U9: - | V9: - | W9: - | X9: - | Y9: - | Z9: - | AA9: 103 | AB9: 103
A10: H_Mr_kz_k | B10: Getijdenrest-geulopvulling | C10: klei, zwak zandig, slap | E10: 0.7 | F10: O | G10: 15 | H10: 18 | I10: 15 | J10: 18 | K10: 0 | L10: Zandige klei, löss, keileem | N10: 29.9 | O10: 32 | P10: 0 | Q10: 8 | R10: #N/A | S10: nee | T10: H_Mr_kz | U10: 0.259 | V10: 0.262 | W10: 0.892 | X10: 0.9 | Y10: 28.42 | Z10: 48.51 | AA10: 60 | AB10: 100
A11: H_Mkw_z&k | B11: Afzettingen van kleine getijdenplaat- en kweldergeulen | C11: klei, zwak zandig, slap | E11: 0.7 | F11: O | G11: 15 | H11: 18 | I11: 15 | J11: 18 | K11: 0 | L11: Zandige klei, löss, keileem | N11: 29.9 | O11: 32 | P11: 0 | Q11: 8 | R11: #N/A | S11: nee | T11: H_Mkw_z&k | U11: 0.259 | V11: 0.262 | W11: 0.892 | X11: 0.9 | Y11: 28.42 | Z11: 48.51 | AA11: 60 | AB11: 100
A12: H_Mp_k | B12: Kleiige getijdenplaat- en kwelderafzettingen | C12: klei, zwak zandig, slap | E12: 0.7 | F12: O | G12: 15 | H12: 18 | I12: 15 | J12: 18 | K12: 0 | L12: Siltige klei | N12: 34 | O12: 42 | P12: 0 | Q12: 8 | R12: #N/A | S12: nee | T12: H_Mp_k | U12: 0.281 | V12: 0.29 | W12: 0.892 | X12: 0.9 | Y12: 11.57 | Z12: 21.92 | AA12: 60 | AB12: 100
A13: H_Mp_ko | B13: Organisch rijke getijdenplaat- en kwelderafzettingen | C13: klei, zwak tot sterk organisch, slap | E13: 0.2 | F13: O | G13: 13 | H13: 15 | I13: 13 | J13: 15 | K13: 0 | L13: Organische klei | N13: 36 | O13: 46 | P13: 0 | Q13: 4.1 | R13: #N/A | S13: nee | T13: H_Mp_ko | U13: 0.306 | V13: 0.315 | W13: 0.891 | X13: 0.9 | Y13: 5.67 | Z13: 17.53 | AA13: 60 | AB13: 100
A14: H_Ml_ko | B14: Lagunaire afzetting | C14: klei, zwak tot sterk organisch, slap | E14: 0.2 | F14: O | G14: 13 | H14: 15 | I14: 13 | J14: 15 | K14: 0 | L14: Organische klei | N14: 36 | O14: 46 | P14: 0 | Q14: 4.1 | R14: #N/A | S14: nee | T14: H_Ml_ko | U14: 0.306 | V14: 0.315 | W14: 0.891 | X14: 0.9 | Y14: 5.67 | Z14: 17.53 | AA14: 60 | AB14: 100
A15: H_Eg_zm_z | B15: Matig fijn tot zeer grof estuarien getijden-geulzand | C15: zand, siltig/kleiig, los | E15: 8 | F15: G | G15: 18 | H15: 19 | I15: 20 | J15: 21 | K15: 0 | L15: Zand met kleilaagjes (getijdenafzettingen) | N15: 29.9 | O15: 32 | P15: 0 | Q15: - | R15: - | S15: nee | T15: nee, gedraineerd | U15: - | V15: - | W15: - | X15: - | Y15: - | Z15: - | AA15: 103 | AB15: 103
A16: H_Eg_zm_k | B16: Matig fijn tot zeer grof estuarien getijden-geulzand | C16: klei, sterk zandig | E16: 1 | F16: O | G16: 18 | H16: 20 | I16: 18 | J16: 20 | K16: 0 | L16: Zand met kleilaagjes (getijdenafzettingen) | N16: 29.9 | O16: 32 | P16: 0 | Q16: 13.3 | R16: #N/A | S16: ja | T16: nee, volgew groter dan 17 | U16: - | V16: - | W16: - | X16: - | Y16: - | Z16: - | AA16: 60 | AB16: 100
A17: H_Eg_z&k_k | B17: Uiterst fijn tot matig fijn estuarien getijden-geulzand | C17: klei, sterk zandig | E17: 1 | F17: O | G17: 18 | H17: 20 | I17: 18 | J17: 20 | K17: 0 | L17: Zand met kleilaagjes (getijdenafzettingen) | N17: 29.9 | O17: 32 | P17: 0 | Q17: 13.3 | R17: #N/A | S17: ja | T17: nee, volgew groter dan 17 | U17: - | V17: - | W17: - | X17: - | Y17: - | Z17: - | AA17: 60 | AB17: 100
A18: H_Eg_z&k_z | B18: Uiterst fijn tot matig fijn estuarien getijden-geulzand | C18: zand, siltig/kleiig, los | E18: 8 | F18: G | G18: 18 | H18: 19 | I18: 20 | J18: 21 | K18: 0 | L18: Zand met kleilaagjes (getijdenafzettingen) | N18: 29.9 | O18: 32 | P18: 0 | Q18: - | R18: - | S18: nee | T18: nee, gedraineerd | U18: - | V18: - | W18: - | X18: - | Y18: - | Z18: - | AA18: 103 | AB18: 103
A19: H_Rg_zg | B19: Zeer grof tot uiterst grof rivierbeddings-zand | C19: zand, matig dicht | E19: 15 | F19: G | G19: 18 | H19: 19 | I19: 20 | J19: 21 | K19: 0 | L19: Matig gesorteerd matig hoekig kwartszand | N19: 32.4 | O19: 34 | P19: 0 | Q19: - | R19: - | S19: nee | T19: nee, gedraineerd | U19: - | V19: - | W19: - | X19: - | Y19: - | Z19: - | AA19: 103 | AB19: 103
A20: H_Rg_zm | B20: Matig fijn tot zeer grof rivierbeddings-zand | C20: zand, los | E20: 5 | F20: G | G20: 17 | H20: 18 | I20: 19 | J20: 20 | K20: 0 | L20: Matig gesorteerd matig hoekig kwartszand | N20: 32.4 | O20: 34 | P20: 0 | Q20: - | R20: - | S20: nee | T20: nee, gedraineerd | U20: - | V20: - | W20: - | X20: - | Y20: - | Z20: - | AA20: 103 | AB20: 103
A21: H_Rg_zf | B21: Uiterst fijn tot matig fijn zand rivierbeddings-zand | C21: zand, los | E21: 5 | F21: G | G21: 17 | H21: 18 | I21: 19 | J21: 20 | K21: 0 | L21: Matig gesorteerd matig hoekig kwartszand | N21: 32.4 | O21: 34 | P21: 0 | Q21: - | R21: - | S21: nee | T21: nee, gedraineerd | U21: - | V21: - | W21: - | X21: - | Y21: - | Z21: - | AA21: 103 | AB21: 103
A22: H_Rr_o&z_k | B22: Rivierrestgeul-opvulling | C22: klei, zwak tot sterk organisch, slap | E22: 0.2 | F22: O | G22: 13 | H22: 15 | I22: 13 | J22: 15 | K22: 0 | L22: Organische klei | N22: 36 | O22: 46 | P22: 0 | Q22: 4.1 | R22: #N/A | S22: nee | T22: H_Rr_o&z | U22: 0.306 | V22: 0.315 | W22: 0.891 | X22: 0.9 | Y22: 5.67 | Z22: 17.53 | AA22: 40 | AB22: 90
A23: H_Rr_o&z_z | B23: Rivierrestgeul-opvulling | C23: zand, siltig/kleiig, los | E23: 8 | F23: G | G23: 18 | H23: 19 | I23: 20 | J23: 21 | K23: 0 | L23: Zand met kleilaagjes (getijdenafzettingen) | N23: 29.9 | O23: 32 | P23: 0 | Q23: - | R23: - | S23: nee | T23: nee, gedraineerd | U23: - | V23: - | W23: - | X23: - | Y23: - | Z23: - | AA23: 103 | AB23: 103
A24: H_Ro_z&k_k | B24: Oever-, crevasse- en dijkdoorbraak-afzettingen | C24: klei, zwak zandig, slap | E24: 0.7 | F24: O | G24: 15 | H24: 18 | I24: 15 | J24: 18 | K24: 0 | L24: Zandige klei, löss, keileem | N24: 29.9 | O24: 32 | P24: 0 | Q24: 8 | R24: #N/A | S24: nee | T24: H_Ro_z&k | U24: 0.259 | V24: 0.262 | W24: 0.892 | X24: 0.9 | Y24: 28.42 | Z24: 48.51 | AA24: 40 | AB24: 90
A25: H_Ro_z&k_z | B25: Oever-, crevasse- en dijkdoorbraak-afzettingen | C25: zand, siltig/kleiig, los | E25: 8 | F25: G | G25: 18 | H25: 19 | I25: 20 | J25: 21 | K25: 0 | L25: Zand met kleilaagjes (getijdenafzettingen) | N25: 29.9 | O25: 32 | P25: 0 | Q25: - | R25: - | S25: nee | T25: nee, gedraineerd | U25: - | V25: - | W25: - | X25: - | Y25: - | Z25: - | AA25: 103 | AB25: 103
A26: H_Rk_k_k | B26: Hogere komafzettingen | C26: klei, slap | E26: 0.5 | F26: O | G26: 14 | H26: 17 | I26: 14 | J26: 17 | K26: 0 | L26: Siltige klei | N26: 34 | O26: 42 | P26: 0 | Q26: 6 | R26: #N/A | S26: nee | T26: H_Rk_k | U26: 0.281 | V26: 0.29 | W26: 0.892 | X26: 0.9 | Y26: 11.57 | Z26: 21.92 | AA26: 40 | AB26: 90
A27: H_Rk_k_z | B27: Hogere komafzettingen | C27: zand, siltig/kleiig, los | D27: Onwaarschijnlijk dat deze voorkomt. IB dient aan te tonen dat de keuze voor deze eenheid correct is. | E27: 8 | F27: G | G27: 18 | H27: 19 | I27: 20 | J27: 21 | K27: 0 | L27: Zand met kleilaagjes (getijdenafzettingen) | N27: 29.9 | O27: 32 | P27: 0 | Q27: - | R27: - | S27: nee | T27: nee, gedraineerd | U27: - | V27: - | W27: - | X27: - | Y27: - | Z27: - | AA27: 103 | AB27: 103
A28: H_Rk_k&v | B28: Lagere komafzettingen met afwisseling van klei- en veenlagen | C28: klei, zwak tot sterk organisch, slap | E28: 0.2 | F28: O | G28: 13 | H28: 15 | I28: 13 | J28: 15 | K28: 0 | L28: Organische klei | N28: 36 | O28: 46 | P28: 0 | Q28: 4.1 | R28: #N/A | S28: nee | T28: H_Rk_k&v | U28: 0.306 | V28: 0.315 | W28: 0.891 | X28: 0.9 | Y28: 5.67 | Z28: 17.53 | AA28: 40 | AB28: 90
A29: H_Rk_ko | B29: Lagere komafzettingen met organische klei | C29: klei, zwak tot sterk organisch, slap | E29: 0.2 | F29: O | G29: 13 | H29: 15 | I29: 13 | J29: 15 | K29: 0 | L29: Organische klei | N29: 36 | O29: 46 | P29: 0 | Q29: 4.1 | R29: #N/A | S29: nee | T29: H_Rk_ko | U29: 0.306 | V29: 0.315 | W29: 0.891 | X29: 0.9 | Y29: 5.67 | Z29: 17.53 | AA29: 40 | AB29: 90
A30: H_Rk_vk | B30: Lagere komafzetting van kleiig veen | C30: veen, slap | E30: 0.1 | F30: O | G30: 10 | H30: 12 | I30: 10 | J30: 12 | K30: 0 | L30: Veen | N30: 30 | O30: 44 | P30: 0 | Q30: 3.4 | R30: #N/A | S30: nee | T30: H_Rk_vk | U30: 0.311 | V30: 0.32 | W30: 0.891 | X30: 0.9 | Y30: 13.43 | Z30: 25.54 | AA30: 35 | AB30: 45
A31: H_Vhv_v | B31: Veen | C31: veen, slap | D31: Dit kan zijn mineraalarm veen, kleiige veen, gyttja | E31: 0.1 | F31: O | G31: 10 | H31: 12 | I31: 10 | J31: 12 | K31: 0 | L31: Veen | N31: 30 | O31: 44 | P31: 0 | Q31: 3.4 | R31: #N/A | S31: nee | T31: H_Vhv_v | U31: 0.391 | V31: 0.395 | W31: 0.892 | X31: 0.9 | Y31: 5.54 | Z31: 14.88 | AA31: 35 | AB31: 45
A32: H_Vbv_v | B32: Gecompacteerd veen | C32: veen, slap | E32: 0.1 | F32: O | G32: 10 | H32: 12 | I32: 10 | J32: 12 | K32: 0 | L32: Veen | N32: 30 | O32: 44 | P32: 0 | Q32: 3.4 | R32: #N/A | S32: nee | T32: H_Vbv_v | U32: 0.3 | V32: 0.31 | W32: 0.8 | X32: 0.9 | Y32: 15 | Z32: 25 | AA32: 35 | AB32: 90
A33: P_Rbk_vk | B33: Lokale beekdalafzettingen van kleiig tot zandig veen | C33: veen, slap | D33: Deze eenheid kan ondiep voorkomen, vandaar keus voor "slap". Kan elders elders steviger zijn, IB dient dat aan te tonen. | E33: 0.1 | F33: O | G33: 10 | H33: 12 | I33: 10 | J33: 12 | K33: 0 | L33: Veen | N33: 30 | O33: 44 | P33: 0 | Q33: 3.4 | R33: #N/A | S33: nee | T33: P_Rbk_vk | U33: 0.311 | V33: 0.32 | W33: 0.891 | X33: 0.9 | Y33: 13.43 | Z33: 25.54 | AA33: 35 | AB33: 90
A34: H_Ova_zm | B34: Matig fijn tot zeer grof zand | C34: zand, los | E34: 5 | F34: G | G34: 17 | H34: 18 | I34: 19 | J34: 20 | K34: 0 | L34: Matig gesorteerd matig hoekig kwartszand | N34: 32.4 | O34: 34 | P34: 0 | Q34: - | R34: - | S34: nee | T34: nee, gedraineerd | U34: - | V34: - | W34: - | X34: - | Y34: - | Z34: - | AA34: 103 | AB34: 103
A35: H_Ova_zf | B35: Uiterst fijn tot matig fijn zand | C35: zand, siltig/kleiig, los | E35: 8 | F35: G | G35: 18 | H35: 19 | I35: 20 | J35: 21 | K35: 0 | L35: Zand met kleilaagjes (getijdenafzettingen) | N35: 29.9 | O35: 32 | P35: 0 | Q35: - | R35: - | S35: nee | T35: nee, gedraineerd | U35: - | V35: - | W35: - | X35: - | Y35: - | Z35: - | AA35: 103 | AB35: 103
A36: H_Aa_z | B36: Aangebracht materiaal, zand baanlichaam | C36: zand, los | E36: 5 | F36: G | G36: 17 | H36: 18 | I36: 19 | J36: 20 | K36: 0 | L36: Baanlichaam zand | N36: 30 | O36: 32 | P36: 0 | Q36: - | R36: - | S36: nee | T36: nee, gedraineerd | U36: - | V36: - | W36: - | X36: - | Y36: - | Z36: - | AA36: 103 | AB36: 103
A37: H_Aa_kz | B37: Aangebracht materiaal, klei baanlichaam | C37: klei, zwak zandig, slap | E37: 0.7 | F37: O | G37: 15 | H37: 18 | I37: 15 | J37: 18 | K37: 0 | L37: Baanlichaam klei, zandige klei | N37: 29.9 | O37: 32 | P37: 0 | Q37: 8 | R37: #N/A | S37: nee | T37: H_Aa_kz | U37: 0.306 | V37: 0.315 | W37: 0.891 | X37: 0.9 | Y37: 5.67 | Z37: 17.53 | AA37: 60 | AB37: 100
A38: H_Aa_ks | B38: Aangebracht materiaal, klei baanlichaam | C38: klei, slap | E38: 0.5 | F38: O | G38: 14 | H38: 17 | I38: 14 | J38: 17 | K38: 0 | L38: Baanlichaam klei, siltige klei | N38: 34 | O38: 42 | P38: 0 | Q38: 6 | R38: #N/A | S38: nee | T38: H_Aa_ks | U38: 0.306 | V38: 0.315 | W38: 0.891 | X38: 0.9 | Y38: 5.67 | Z38: 17.53 | AA38: 60 | AB38: 100
A39: H_Aa_ko | B39: Aangebracht materiaal, klei baanlichaam | C39: klei, zwak tot sterk organisch, slap | E39: 0.2 | F39: O | G39: 13 | H39: 15 | I39: 13 | J39: 15 | K39: 0 | L39: Baanlichaam klei, organische klei | N39: 36 | O39: 46 | P39: 0 | Q39: 4.1 | R39: #N/A | S39: nee | T39: H_Aa_ko | U39: 0.306 | V39: 0.315 | W39: 0.891 | X39: 0.9 | Y39: 5.67 | Z39: 17.53 | AA39: 45 | AB39: 90
A40: H_Aa_onb | B40: Aangebracht materiaal, baanlichaam | C40: klei, zwak tot sterk organisch, slap | D40: Dit is de meest conservatieve keuze. In gebieden waar vooral zand dicht onder het oppervlak ligt kiezen voor Zand, siltig/kleiig, los. | E40: 0.2 | F40: O | G40: 13 | H40: 15 | I40: 13 | J40: 15 | K40: 0 | L40: Baanlichaam onbekend | N40: 30 | O40: 44 | P40: 0 | Q40: 4.1 | R40: #N/A | S40: nee | T40: H_Aa_onb_k | U40: 0.306 | V40: 0.315 | W40: 0.891 | X40: 0.9 | Y40: 5.67 | Z40: 17.53 | AA40: 45 | AB40: 90
...

Sheet Kleurtabel
B1: R | C1: G | D1: B | E1: A
A2: H_Aa_kz | B2: 245 | C2: 245 | D2: 245 | E2: 128 | F2: ="#"&DEC2HEX(E2,2)&DEC2HEX(B2,2)&DEC2HEX(C2,2)&DEC2HEX(D2,2) -> #80F5F5F5
A3: H_Aa_onb_z | B3: 245 | C3: 245 | D3: 244 | E3: 128 | F3: ="#"&DEC2HEX(E3,2)&DEC2HEX(B3,2)&DEC2HEX(C3,2)&DEC2HEX(D3,2) -> #80F5F5F4
A4: H_Aa_z | B4: 245 | C4: 245 | D4: 245 | E4: 128 | F4: ="#"&DEC2HEX(E4,2)&DEC2HEX(B4,2)&DEC2HEX(C4,2)&DEC2HEX(D4,2) -> #80F5F5F5
A5: H_Mg_zf | B5: 196 | C5: 255 | D5: 117 | E5: 128 | F5: ="#"&DEC2HEX(E5,2)&DEC2HEX(B5,2)&DEC2HEX(C5,2)&DEC2HEX(D5,2) -> #80C4FF75
A6: H_Mg_zk | B6: 163 | C6: 255 | D6: 71 | E6: 128 | F6: ="#"&DEC2HEX(E6,2)&DEC2HEX(B6,2)&DEC2HEX(C6,2)&DEC2HEX(D6,2) -> #80A3FF47
A7: H_Mkw_z&k | B7: 153 | C7: 204 | D7: 0 | E7: 128 | F7: ="#"&DEC2HEX(E7,2)&DEC2HEX(B7,2)&DEC2HEX(C7,2)&DEC2HEX(D7,2) -> #8099CC00
A8: H_Mp_k | B8: 0 | C8: 128 | D8: 128 | E8: 128 | F8: ="#"&DEC2HEX(E8,2)&DEC2HEX(B8,2)&DEC2HEX(C8,2)&DEC2HEX(D8,2) -> #80008080
A9: H_Vbv_v | B9: 116 | C9: 39 | D9: 0 | E9: 128 | F9: ="#"&DEC2HEX(E9,2)&DEC2HEX(B9,2)&DEC2HEX(C9,2)&DEC2HEX(D9,2) -> #80742700
A10: H_Vhv_v | B10: 153 | C10: 51 | D10: 0 | E10: 128 | F10: ="#"&DEC2HEX(E10,2)&DEC2HEX(B10,2)&DEC2HEX(C10,2)&DEC2HEX(D10,2) -> #80993300
A11: P_Rbk_z&s_s | B11: 231 | C11: 226 | D11: 0 | E11: 128 | F11: ="#"&DEC2HEX(E11,2)&DEC2HEX(B11,2)&DEC2HEX(C11,2)&DEC2HEX(D11,2) -> #80E7E200
A12: P_Rg_zm | B12: 255 | C12: 204 | D12: 0 | E12: 128 | F12: ="#"&DEC2HEX(E12,2)&DEC2HEX(B12,2)&DEC2HEX(C12,2)&DEC2HEX(D12,2) -> #80FFCC00
A13: P_Wdz_zf | B13: 255 | C13: 255 | D13: 102 | E13: 128 | F13: ="#"&DEC2HEX(E13,2)&DEC2HEX(B13,2)&DEC2HEX(C13,2)&DEC2HEX(D13,2) -> #80FFFF66
... A53: H_Ml_ko | B53: 0 | C53: 111 | D53: 108 | E53: 128 | F53: ="#"&DEC2HEX(E53,2)&DEC2HEX(B53,2)&DEC2HEX(C53,2)&DEC2HEX(D53,2) -> #80006F6C
E54: 0 | F54: ="#"&DEC2HEX(E54,2)&DEC2HEX(B54,2)&DEC2HEX(C54,2)&DEC2HEX(D54,2) -> #00000000
A55: H_Mg_zm | E55: 0 | F55: ="#"&DEC2HEX(E55,2)&DEC2HEX(B55,2)&DEC2HEX(C55,2)&DEC2HEX(D55,2) -> #00000000
A56: H_Mg_zf | E56: 0 | F56: ="#"&DEC2HEX(E56,2)&DEC2HEX(B56,2)&DEC2HEX(C56,2)&DEC2HEX(D56,2) -> #00000000
A57: H_Mg_zk | E57: 0 | F57: ="#"&DEC2HEX(E57,2)&DEC2HEX(B57,2)&DEC2HEX(C57,2)&DEC2HEX(D57,2) -> #00000000
A58: H_Mp_zf | E58: 0 | F58: #00000000
A59: H_Mr_kz_z | E59: 0 | F59: #00000000
A60: H_Mr_kz_k | E60: 0 | F60: #00000000
A61: H_Mkw_z&k | E61: 0 | F61: #00000000
A62: H_Mp_k | E62: 0 | F62: #00000000
A63: H_Mp_ko | E63: 0 | F63: #00000000
A64: H_Ml_ko | E64: 0 | F64: #00000000
A65: H_Eg_zm_z | E65: 0 | F65: #00000000
A66: H_Eg_zm_k | E66: 0 | F66: #00000000
A67: H_Eg_z&k_k | E67: 0 | F67: #00000000
A68: H_Eg_z&k_z | E68: 0 | F68: #00000000
A69: H_Rg_zg | E69: 0 | F69: #00000000
... A118: K_Mm_s | E118: 0 | F118: #00000000

Sheet stochastic_parameters_LN
A2: Stochastic parameters for log-normal disributions back-calculated from Tabel
A4: color legend:
A5: copied from tabel
A6: back-calculated
A7: manual
A8: SOS Code | F8: γd [kN/m3] | N8: γn [kN/m3] | V8: phi [kN/m3] | AD8: S [kN/m3] | AL8: m [kN/m3] | AT8: POP [kN/m3] | BB8: Su_min / cu_min [kPa] | BF8: scipy.stats | BJ8: vs [kN/m3]
E9: LNA-based colorscale | F9: char_low (= 5%) | G9: char_high (= 95%) | H9: mu_lnX | I9: sig_ln(X) (=s) | J9: median (=scale) | K9: mean | L9: st.dev | M9: CoV | N9: char_low (= 5%) | O9: char_high (= 95%) | P9: mu_ln(X) | Q9: sig_ln(X) (=s) | R9: median (=scale) | S9: mean | T9: st.dev | U9: CoV | V9: char_low (= 5%) | W9: char_high (= 95%) | X9: mu_ln(X) | Y9: sig_ln(X) (=s) | Z9: median (=scale) | AA9: mean | AB9: st.dev | AC9: CoV | AD9: char_low (= 5%) | AE9: char_high (= 95%) | AF9: mu_ln(X) | AG9: sig_ln(X) (=s) | AH9: median (=scale) | AI9: mean | AJ9: st.dev | AK9: CoV | AL9: char_low (= 5%) | AM9: char_high (= 95%) | AN9: mu_ln(X) | AO9: sig_ln(X) (=s) | AP9: median (=scale) | AQ9: mean | AR9: st.dev | AS9: CoV | AT9: char_low (= 5%) | AU9: char_high (= 95%) | AV9: mu_ln(X) | AW9: sig_ln(X) (=s) | AX9: median (=scale) | AY9: mean | AZ9: st.dev | BA9: CoV | BB9: char_low (= 5%) | BC9: char_high (= 95%) | BD9: mu_ln(X) | BE9: sig_ln(X) (=s) | BF9: median (=scale) | BG9: mean | BH9: st.dev | BI9: CoV | BJ9: char_low (= 5%) | BK9: char_high (= 95%) | BL9: mu_lnX | BM9: sig_ln(X) (=s) | BN9: median (=scale) | BO9: mean | BP9: st.dev | BQ9: CoV
C10: tabelkolom | F10: 7 | G10: 8 | H10: - | I10: - | K10: - | L10: - | M10: - | N10: 9 | O10: 10 | P10: - | Q10: - | S10: - | T10: - | U10: - | V10: 14 | X10: - | Y10: - | AA10: 15 | AB10: - | AC10: - | AD10: 21 | AF10: - | AG10: - | AI10: 22 | AJ10: - | AK10: - | AL10: 23 | AN10: - | AO10: - | AQ10: 24 | AR10: - | AS10: - | AT10: 25 | AV10: - | AW10: - | AY10: 26 | AZ10: - | BA10: - | BB10: 17 | BD10: - | BE10: - | BG10: X | BH10: - | BI10: - | BJ10: 27 | BK10: 28 | BL10: - | BM10: - | BO10: - | BP10: - | BQ10: -
A11: Code | B11: mapping | C11: empty | D11: shading | E11: color | F11: gamma_dry_char_low | G11: gamma_dry_char_high | H11: gamma_dry_mu | I11: gamma_dry_sig | J11: gamma_dry_median | K11: gamma_dry_mean | L11: gamma_dry_std | M11: gamma_dry_cov | N11: gamma_wet_char_low | O11: gamma_wet_char_high | P11: gamma_wet_mu | Q11: gamma_wet_sig | R11: gamma_wet_median | S11: gamma_wet_mean | T11: gamma_wet_std | U11: gamma_wet_cov | V11: phi_char_low | W11: phi_char_high | X11: phi_mu | Y11: phi_sig | Z11: phi_median | AA11: phi_mean | AB11: phi_std | AC11: phi_cov | AD11: S_char_low | AE11: S_char_high | AF11: S_mu | AG11: S_sig | AH11: S_median | AI11: S_mean | AJ11: S_std | AK11: S_cov | AL11: m_char_low | AM11: m_char_high | AN11: m_mu | AO11: m_sig | AP11: m_median | AQ11: m_mean | AR11: m_std | AS11: m_cov | AT11: POP_char_low | AU11: POP_char_high | AV11: POP_mu | AW11: POP_sig | AX11: POP_median | AY11: POP_mean | AZ11: POP_std | BA11: POP_cov | BB11: Sumin_char_low | BC11: Sumin_char_high | BD11: Sumin_mu | BE11: Sumin_sig | BF11: Sumin_median | BG11: Sumin_mean | BH11: Sumin_std | BI11: Sumin_cov | BJ11: vs_char_low | BK11: vs_char_high | BL11: vs_mu | BM11: vs_sig | BN11: vs_median | BO11: vs_mean | BP11: vs_std | BQ11: vs_cov
A12: H_Mg_zm | B12: TABLE | E12: =VLOOKUP(A12,Kleurtabel!$A$2:$F$822,6,FALSE) -> #80F2DD40 | F12: =VLOOKUP($A12,TABEL,F$10,FALSE) -> 18 | G12: =VLOOKUP($A12,TABEL,G$10,FALSE) -> 19 | H12: =(LN(G12)+LN(F12))/2 -> 2.9174054 | I12: =(LN(G12)-LN(F12))/(2*1.645) -> 0.016433806 | J12: =IF(F12="-","-",EXP(H12)) -> 18.493242 | K12: =EXP(H12+I12*I12/2) -> 18.495739 | L12: =SQRT((EXP(I12*I12)-1)*EXP(2*H12+I12*I12)) -> 0.30397591 | M12: =L12/K12 -> 0.016434915 | N12: =VLOOKUP($A12,TABEL,N$10,FALSE) -> 20 | O12: =VLOOKUP($A12,TABEL,O$10,FALSE) -> 21 | P12: =(LN(O12)+LN(N12))/2 -> 3.0201274 | Q12: =(LN(O12)-LN(N12))/(2*1.645) -> 0.014829837 | R12: =EXP(P12) -> 20.493902 | S12: =EXP(P12+Q12*Q12/2) -> 20.496155 | T12: =SQRT((EXP(Q12*Q12)-1)*EXP(2*P12+Q12*Q12)) -> 0.30397136 | U12: =T12/S12 -> 0.014830653 | V12: =VLOOKUP($A12,TABEL,V$10,FALSE)/2+AA12/2 -> 33.2 | W12: =IF(V12="-","-",EXP(X12+1.645*Y12)) -> 34.812046 | X12: =IF(V12="-","-",LN(AA12)-Y12*Y12/2) -> 3.5262567 | Y12: =IF(V12="-","-",(SQRT(1.645^2+2*LN(AA12/V12))-1.645)) -> 0.014411431 | Z12: =IF(V12="-","-",EXP(X12)) -> 33.996469 | AA12: =VLOOKUP($A12,TABEL,AA$10,FALSE) -> 34 | AB12: =IF(V12="-","-",SQRT((EXP(Y12*Y12)-1)*EXP(2*X12+Y12*Y12))) -> 0.4900141 | AC12: =IF(V12="-","-",AB12/AA12) -> 0.014412179 | AD12: =VLOOKUP($A12,TABEL,AD$10,FALSE) -> - | AE12: =IF(AD12="-","-",EXP(AF12+1.645*AG12)) -> - | AF12: =IF(AD12="-","-",LN(AI12)-AG12*AG12/2) -> - | AG12: =IF(AD12="-","-",(SQRT(1.645^2+2*LN(AI12/AD12))-1.645)) -> - | AH12: =IF(AD12="-","-",EXP(AF12)) -> - | AI12: =VLOOKUP($A12,TABEL,AI$10,FALSE) -> - | AJ12: =IF(AD12="-","-",SQRT((EXP(AG12*AG12)-1)*EXP(2*AF12+AG12*AG12))) -> - | AK12: =IF(AD12="-","-",AJ12/AI12) -> - | AL12: =VLOOKUP($A12,TABEL,AL$10,FALSE) -> - | AM12: =IF(AL12="-","-",EXP(AN12+1.645*AO12)) -> - | AN12: =IF(AL12="-","-",LN(AQ12)-AO12*AO12/2) -> - | AO12: =IF(AL12="-","-",(SQRT(1.645^2+2*LN(AQ12/AL12))-1.645)) -> - | AP12: =IF(AL12="-","-",EXP(AN12)) -> - | AQ12: =VLOOKUP($A12,TABEL,AQ$10,FALSE) -> - | AR12: =IF(AL12="-","-",SQRT((EXP(AO12*AO12)-1)*EXP(2*AN12+AO12*AO12))) -> - | AS12: =IF(AL12="-","-",AR12/AQ12) -> - | AT12: =VLOOKUP($A12,TABEL,AT$10,FALSE) -> - | AU12: =IF(AT12="-","-",EXP(AV12+1.645*AW12)) -> - | AV12: =IF(AT12="-","-",LN(AY12)-AW12*AW12/2) -> - | AW12: =IF(AT12="-","-",(SQRT(1.645^2+2*LN(AY12/AT12))-1.645)) -> - | AX12: =IF(AT12="-","-",EXP(AV12)) -> - | AY12: =VLOOKUP($A12,TABEL,AY$10,FALSE) -> - | AZ12: =IF(AT12="-","-",SQRT((EXP(AW12*AW12)-1)*EXP(2*AV12+AW12*AW12))) -> - | BA12: =IF(AT12="-","-",AZ12/AY12) -> - | BB12: =VLOOKUP($A12,TABEL,BB$10,FALSE) -> - | BC12: =IF(BB12="-","-",EXP(BD12+1.645*BE12)) -> - | BD12: =IF(BB12="-","-",LN(BG12)-BE12*BE12/2) -> - | BE12: =IF(BB12="-","-",(SQRT(1.645^2+2*LN(BG12/BB12))-1.645)) -> - | BF12: =IF(BB12="-","-",EXP(BD12)) -> - | BG12: =BB12 -> - | BH12: =IF(BB12="-","-",SQRT((EXP(BE12*BE12)-1)*EXP(2*BD12+BE12*BE12))) -> - | BI12: =IF(BB12="-","-",BH12/BG12) -> - | BJ12: =VLOOKUP($A12,TABEL,BJ$10,FALSE) -> 103 | BK12: =VLOOKUP($A12,TABEL,BK$10,FALSE) -> 103 | BL12: =(LN(BK12)+LN(BJ12))/2 -> 4.634729 | BM12: =(LN(BK12)-LN(BJ12))/(2*1.645) -> 0 | BN12: =IF(BJ12="-","-",EXP(BL12)) -> 103 | BO12: =EXP(BL12+BM12*BM12/2) -> 103 | BP12: =SQRT((EXP(BM12*BM12)-1)*EXP(2*BL12+BM12*BM12)) -> 0 | BQ12: =BP12/BO12 -> 0
A13: H_Mg_zf | B13: TABLE | E13: =VLOOKUP(A13,Kleurtabel!$A$2:$F$822,6,FALSE) -> #80C4FF75 | F13: =VLOOKUP($A13,TABEL,F$10,FALSE) -> 18 | G13: =VLOOKUP($A13,TABEL,G$10,FALSE) -> 19 | H13: =(LN(G13)+LN(F13))/2 -> 2.9174054 | I13: =(LN(G13)-LN(F13))/(2*1.645) -> 0.016433806 | J13: =IF(F13="-","-",EXP(H13)) -> 18.493242 | K13: =EXP(H13+I13*I13/2) -> 18.495739 | L13: =SQRT((EXP(I13*I13)-1)*EXP(2*H13+I13*I13)) -> 0.30397591 | M13: =L13/K13 -> 0.016434915 | N13: =VLOOKUP($A13,TABEL,N$10,FALSE) -> 20 | O13: =VLOOKUP($A13,TABEL,O$10,FALSE) -> 21 | P13: =(LN(O13)+LN(N13))/2 -> 3.0201274 | Q13: =(LN(O13)-LN(N13))/(2*1.645) -> 0.014829837 | R13: =EXP(P13) -> 20.493902 | S13: =EXP(P13+Q13*Q13/2) -> 20.496155 | T13: =SQRT((EXP(Q13*Q13)-1)*EXP(2*P13+Q13*Q13)) -> 0.30397136 | U13: =T13/S13 -> 0.014830653 | V13: =VLOOKUP($A13,TABEL,V$10,FALSE)/2+AA13/2 -> 30.95 | W13: =IF(V13="-","-",EXP(X13+1.645*Y13)) -> 33.072181 | X13: =IF(V13="-","-",LN(AA13)-Y13*Y13/2) -> 3.4655327 | Y13: =IF(V13="-","-",(SQRT(1.645^2+2*LN(AA13/V13))-1.645)) -> 0.020157893 | Z13: =IF(V13="-","-",EXP(X13)) -> 31.993499 | AA13: =VLOOKUP($A13,TABEL,AA$10,FALSE) -> 32 | AB13: =IF(V13="-","-",SQRT((EXP(Y13*Y13)-1)*EXP(2*X13+Y13*Y13))) -> 0.6451181 | AC13: =IF(V13="-","-",AB13/AA13) -> 0.020159941 | AD13: =VLOOKUP($A13,TABEL,AD$10,FALSE) -> - | AE13: =IF(AD13="-","-",EXP(AF13+1.645*AG13)) -> - | AF13: =IF(AD13="-","-",LN(AI13)-AG13*AG13/2) -> - | AG13: =IF(AD13="-","-",(SQRT(1.645^2+2*LN(AI13/AD13))-1.645)) -> - | AH13: =IF(AD13="-","-",EXP(AF13)) -> - | AI13: =VLOOKUP($A13,TABEL,AI$10,FALSE) -> - | AJ13: =IF(AD13="-","-",SQRT((EXP(AG13*AG13)-1)*EXP(2*AF13+AG13*AG13))) -> - | AK13: =IF(AD13="-","-",AJ13/AI13) -> - | AL13: =VLOOKUP($A13,TABEL,AL$10,FALSE) -> - | AM13: =IF(AL13="-","-",EXP(AN13+1.645*AO13)) -> - | AN13: =IF(AL13="-","-",LN(AQ13)-AO13*AO13/2) -> - | AO13: =IF(AL13="-","-",(SQRT(1.645^2+2*LN(AQ13/AL13))-1.645)) -> - | AP13: =IF(AL13="-","-",EXP(AN13)) -> - | AQ13: =VLOOKUP($A13,TABEL,AQ$10,FALSE) -> - | AR13: =IF(AL13="-","-",SQRT((EXP(AO13*AO13)-1)*EXP(2*AN13+AO13*AO13))) -> - | AS13: =IF(AL13="-","-",AR13/AQ13) -> - | AT13: =VLOOKUP($A13,TABEL,AT$10,FALSE) -> - | AU13: =IF(AT13="-","-",EXP(AV13+1.645*AW13)) -> - | AV13: =IF(AT13="-","-",LN(AY13)-AW13*AW13/2) -> - | AW13: =IF(AT13="-","-",(SQRT(1.645^2+2*LN(AY13/AT13))-1.645)) -> - | AX13: =IF(AT13="-","-",EXP(AV13)) -> - | AY13: =VLOOKUP($A13,TABEL,AY$10,FALSE) -> - | AZ13: =IF(AT13="-","-",SQRT((EXP(AW13*AW13)-1)*EXP(2*AV13+AW13*AW13))) -> - | BA13: =IF(AT13="-","-",AZ13/AY13) -> - | BB13: =VLOOKUP($A13,TABEL,BB$10,FALSE) -> - | BC13: =IF(BB13="-","-",EXP(BD13+1.645*BE13)) -> - | BD13: =IF(BB13="-","-",LN(BG13)-BE13*BE13/2) -> - | BE13: =IF(BB13="-","-",(SQRT(1.645^2+2*LN(BG13/BB13))-1.645)) -> - | BF13: =IF(BB13="-","-",EXP(BD13)) -> - | BG13: =BB13 -> - | BH13: =IF(BB13="-","-",SQRT((EXP(BE13*BE13)-1)*EXP(2*BD13+BE13*BE13))) -> - | BI13: =IF(BB13="-","-",BH13/BG13) -> - | BJ13: =VLOOKUP($A13,TABEL,BJ$10,FALSE) -> 103 | BK13: =VLOOKUP($A13,TABEL,BK$10,FALSE) -> 103 | BL13: =(LN(BK13)+LN(BJ13))/2 -> 4.634729 | BM13: =(LN(BK13)-LN(BJ13))/(2*1.645) -> 0 | BN13: =IF(BJ13="-","-",EXP(BL13)) -> 103 | BO13: =EXP(BL13+BM13*BM13/2) -> 103 | BP13: =SQRT((EXP(BM13*BM13)-1)*EXP(2*BL13+BM13*BM13)) -> 0 | BQ13: =BP13/BO13 -> 0
A14: H_Mg_zk | B14: TABLE | E14: =VLOOKUP(A14,Kleurtabel!$A$2:$F$822,6,FALSE) -> #80A3FF47 | F14: =VLOOKUP($A14,TABEL,F$10,FALSE) -> 18 | G14: =VLOOKUP($A14,TABEL,G$10,FALSE) -> 19 | H14: =(LN(G14)+LN(F14))/2 -> 2.9174054 | I14: =(LN(G14)-LN(F14))/(2*1.645) -> 0.016433806 | J14: =IF(F14="-","-",EXP(H14)) -> 18.493242 | K14: =EXP(H14+I14*I14/2) -> 18.495739 | L14: =SQRT((EXP(I14*I14)-1)*EXP(2*H14+I14*I14)) -> 0.30397591 | M14: =L14/K14 -> 0.016434915 | N14: =VLOOKUP($A14,TABEL,N$10,FALSE) -> 20 | O14: =VLOOKUP($A14,TABEL,O$10,FALSE) -> 21 | P14: =(LN(O14)+LN(N14))/2 -> 3.0201274 | Q14: =(LN(O14)-LN(N14))/(2*1.645) -> 0.014829837 | R14: =EXP(P14) -> 20.493902 | S14: =EXP(P14+Q14*Q14/2) -> 20.496155 | T14: =SQRT((EXP(Q14*Q14)-1)*EXP(2*P14+Q14*Q14)) -> 0.30397136 | U14: =T14/S14 -> 0.014830653 | V14: =VLOOKUP($A14,TABEL,V$10,FALSE)/2+AA14/2 -> 30.95 | W14: =IF(V14="-","-",EXP(X14+1.645*Y14)) -> 33.072181 | X14: =IF(V14="-","-",LN(AA14)-Y14*Y14/2) -> 3.4655327 | Y14: =IF(V14="-","-",(SQRT(1.645^2+2*LN(AA14/V14))-1.645)) -> 0.020157893 | Z14: =IF(V14="-","-",EXP(X14)) -> 31.993499 | AA14: =VLOOKUP($A14,TABEL,AA$10,FALSE) -> 32 | AB14: =IF(V14="-","-",SQRT((EXP(Y14*Y14)-1)*EXP(2*X14+Y14*Y14))) -> 0.6451181 | AC14: =IF(V14="-","-",AB14/AA14) -> 0.020159941 | AD14: =VLOOKUP($A14,TABEL,AD$10,FALSE) -> - | AE14: =IF(AD14="-","-",EXP(AF14+1.645*AG14)) -> - | AF14: =IF(AD14="-","-",LN(AI14)-AG14*AG14/2) -> - | AG14: =IF(AD14="-","-",(SQRT(1.645^2+2*LN(AI14/AD14))-1.645)) -> - | AH14: =IF(AD14="-","-",EXP(AF14)) -> - | AI14: =VLOOKUP($A14,TABEL,AI$10,FALSE) -> - | AJ14: =IF(AD14="-","-",SQRT((EXP(AG14*AG14)-1)*EXP(2*AF14+AG14*AG14))) -> - | AK14: =IF(AD14="-","-",AJ14/AI14) -> - | AL14: =VLOOKUP($A14,TABEL,AL$10,FALSE) -> - | AM14: =IF(AL14="-","-",EXP(AN14+1.645*AO14)) -> - | AN14: =IF(AL14="-","-",LN(AQ14)-AO14*AO14/2) -> - | AO14: =IF(AL14="-","-",(SQRT(1.645^2+2*LN(AQ14/AL14))-1.645)) -> - | AP14: =IF(AL14="-","-",EXP(AN14)) -> - | AQ14: =VLOOKUP($A14,TABEL,AQ$10,FALSE) -> - | AR14: =IF(AL14="-","-",SQRT((EXP(AO14*AO14)-1)*EXP(2*AN14+AO14*AO14))) -> - | AS14: =IF(AL14="-","-",AR14/AQ14) -> - | AT14: =VLOOKUP($A14,TABEL,AT$10,FALSE) -> - | AU14: =IF(AT14="-","-",EXP(AV14+1.645*AW14)) -> - | AV14: =IF(AT14="-","-",LN(AY14)-AW14*AW14/2) -> - | AW14: =IF(AT14="-","-",(SQRT(1.645^2+2*LN(AY14/AT14))-1.645)) -> - | AX14: =IF(AT14="-","-",EXP(AV14)) -> - | AY14: =VLOOKUP($A14,TABEL,AY$10,FALSE) -> - | AZ14: =IF(AT14="-","-",SQRT((EXP(AW14*AW14)-1)*EXP(2*AV14+AW14*AW14))) -> - | BA14: =IF(AT14="-","-",AZ14/AY14) -> - | BB14: =VLOOKUP($A14,TABEL,BB$10,FALSE) -> - | BC14: =IF(BB14="-","-",EXP(BD14+1.645*BE14)) -> - | BD14: =IF(BB14="-","-",LN(BG14)-BE14*BE14/2) -> - | BE14: =IF(BB14="-","-",(SQRT(1.645^2+2*LN(BG14/BB14))-1.645)) -> - | BF14: =IF(BB14="-","-",EXP(BD14)) -> - | BG14: =BB14 -> - | BH14: =IF(BB14="-","-",SQRT((EXP(BE14*BE14)-1)*EXP(2*BD14+BE14*BE14))) -> - | BI14: =IF(BB14="-","-",BH14/BG14) -> - | BJ14: =VLOOKUP($A14,TABEL,BJ$10,FALSE) -> 103 | BK14: =VLOOKUP($A14,TABEL,BK$10,FALSE) -> 103 | BL14: =(LN(BK14)+LN(BJ14))/2 -> 4.634729 | BM14: =(LN(BK14)-LN(BJ14))/(2*1.645) -> 0 | BN14: =IF(BJ14="-","-",EXP(BL14)) -> 103 | BO14: =EXP(BL14+BM14*BM14/2) -> 103 | BP14: =SQRT((EXP(BM14*BM14)-1)*EXP(2*BL14+BM14*BM14)) -> 0 | BQ14: =BP14/BO14 -> 0
A15: H_Mp_zf | B15: TABLE | E15: =VLOOKUP(A15,Kleurtabel!$A$2:$F$822,6,FALSE) -> #8033CCCC | F15: =VLOOKUP($A15,TABEL,F$10,FALSE) -> 17 | G15: =VLOOKUP($A15,TABEL,G$10,FALSE) -> 18 | H15: =(LN(G15)+LN(F15))/2 -> 2.8617926 | I15: =(LN(G15)-LN(F15))/(2*1.645) -> 0.017373378 | J15: =IF(F15="-","-",EXP(H15)) -> 17.492856 | K15: =EXP(H15+I15*I15/2) -> 17.495496 | L15: =SQRT((EXP(I15*I15)-1)*EXP(2*H15+I15*I15)) -> 0.3039788 | M15: =L15/K15 -> 0.017374689 | N15: =VLOOKUP($A15,TABEL,N$10,FALSE) -> 19 | O15: =VLOOKUP($A15,TABEL,O$10,FALSE) -> 20 | P15: =(LN(O15)+LN(N15))/2 -> 2.9700856 | Q15: =(LN(O15)-LN(N15))/(2*1.645) -> 0.015590667 | R15: =EXP(P15) -> 19.493589 | S15: =EXP(P15+Q15*Q15/2) -> 19.495958 | T15: =SQRT((EXP(Q15*Q15)-1)*EXP(2*P15+Q15*Q15)) -> 0.30397346 | U15: =T15/S15 -> 0.015591614 | V15: =VLOOKUP($A15,TABEL,V$10,FALSE)/2+AA15/2 -> 30.95 | W15: =IF(V15="-","-",EXP(X15+1.645*Y15)) -> 33.072181 | X15: =IF(V15="-","-",LN(AA15)-Y15*Y15/2) -> 3.4655327 | Y15: =IF(V15="-","-",(SQRT(1.645^2+2*LN(AA15/V15))-1.645)) -> 0.020157893 | Z15: =IF(V15="-","-",EXP(X15)) -> 31.993499 | AA15: =VLOOKUP($A15,TABEL,AA$10,FALSE) -> 32 | AB15: =IF(V15="-","-",SQRT((EXP(Y15*Y15)-1)*EXP(2*X15+Y15*Y15))) -> 0.6451181 | AC15: =IF(V15="-","-",AB15/AA15) -> 0.020159941 | AD15: =VLOOKUP($A15,TABEL,AD$10,FALSE) -> - | AE15: =IF(AD15="-","-",EXP(AF15+1.645*AG15)) -> - | AF15: =IF(AD15="-","-",LN(AI15)-AG15*AG15/2) -> - | AG15: =IF(AD15="-","-",(SQRT(1.645^2+2*LN(AI15/AD15))-1.645)) -> - | AH15: =IF(AD15="-","-",EXP(AF15)) -> - | AI15: =VLOOKUP($A15,TABEL,AI$10,FALSE) -> - | AJ15: =IF(AD15="-","-",SQRT((EXP(AG15*AG15)-1)*EXP(2*AF15+AG15*AG15))) -> - | AK15: =IF(AD15="-","-",AJ15/AI15) -> - | AL15: =VLOOKUP($A15,TABEL,AL$10,FALSE) -> - | AM15: =IF(AL15="-","-",EXP(AN15+1.645*AO15)) -> - | AN15: =IF(AL15="-","-",LN(AQ15)-AO15*AO15/2) -> - | AO15: =IF(AL15="-","-",(SQRT(1.645^2+2*LN(AQ15/AL15))-1.645)) -> - | AP15: =IF(AL15="-","-",EXP(AN15)) -> - | AQ15: =VLOOKUP($A15,TABEL,AQ$10,FALSE) -> - | AR15: =IF(AL15="-","-",SQRT((EXP(AO15*AO15)-1)*EXP(2*AN15+AO15*AO15))) -> - | AS15: =IF(AL15="-","-",AR15/AQ15) -> - | AT15: =VLOOKUP($A15,TABEL,AT$10,FALSE) -> - | AU15: =IF(AT15="-","-",EXP(AV15+1.645*AW15)) -> - | AV15: =IF(AT15="-","-",LN(AY15)-AW15*AW15/2) -> - | AW15: =IF(AT15="-","-",(SQRT(1.645^2+2*LN(AY15/AT15))-1.645)) -> - | AX15: =IF(AT15="-","-",EXP(AV15)) -> - | AY15: =VLOOKUP($A15,TABEL,AY$10,FALSE) -> - | AZ15: =IF(AT15="-","-",SQRT((EXP(AW15*AW15)-1)*EXP(2*AV15+AW15*AW15))) -> - | BA15: =IF(AT15="-","-",AZ15/AY15) -> - | BB15: =VLOOKUP($A15,TABEL,BB$10,FALSE) -> - | BC15: =IF(BB15="-","-",EXP(BD15+1.645*BE15)) -> - | BD15: =IF(BB15="-","-",LN(BG15)-BE15*BE15/2) -> - | BE15: =IF(BB15="-","-",(SQRT(1.645^2+2*LN(BG15/BB15))-1.645)) -> - | BF15: =IF(BB15="-","-",EXP(BD15)) -> - | BG15: =BB15 -> - | BH15: =IF(BB15="-","-",SQRT((EXP(BE15*BE15)-1)*EXP(2*BD15+BE15*BE15))) -> - | BI15: =IF(BB15="-","-",BH15/BG15) -> - | BJ15: =VLOOKUP($A15,TABEL,BJ$10,FALSE) -> 103 | BK15: =VLOOKUP($A15,TABEL,BK$10,FALSE) -> 103 | BL15: =(LN(BK15)+LN(BJ15))/2 -> 4.634729 | BM15: =(LN(BK15)-LN(BJ15))/(2*1.645) -> 0 | BN15: =IF(BJ15="-","-",EXP(BL15)) -> 103 | BO15: =EXP(BL15+BM15*BM15/2) -> 103 | BP15: =SQRT((EXP(BM15*BM15)-1)*EXP(2*BL15+BM15*BM15)) -> 0 | BQ15: =BP15/BO15 -> 0
A16: H_Mr_kz_z | B16: SILTY_CLAY | E16: =VLOOKUP(A16,Kleurtabel!$A$2:$F$822,6,FALSE) -> #80008080 | F16: =VLOOKUP($A16,TABEL,F$10,FALSE) -> 18 | G16: =VLOOKUP($A16,TABEL,G$10,FALSE) -> 19 | H16: =(LN(G16)+LN(F16))/2 -> 2.9174054 | I16: =(LN(G16)-LN(F16))/(2*1.645) -> 0.016433806 | J16: =IF(F16="-","-",EXP(H16)) -> 18.493242 | K16: =EXP(H16+I16*I16/2) -> 18.495739 | L16: =SQRT((EXP(I16*I16)-1)*EXP(2*H16+I16*I16)) -> 0.30397591 | M16: =L16/K16 -> 0.016434915 | N16: =VLOOKUP($A16,TABEL,N$10,FALSE) -> 20 | O16: =VLOOKUP($A16,TABEL,O$10,FALSE) -> 21 | P16: =(LN(O16)+LN(N16))/2 -> 3.0201274 | Q16: =(LN(O16)-LN(N16))/(2*1.645) -> 0.014829837 | R16: =EXP(P16) -> 20.493902 | S16: =EXP(P16+Q16*Q16/2) -> 20.496155 | T16: =SQRT((EXP(Q16*Q16)-1)*EXP(2*P16+Q16*Q16)) -> 0.30397136 | U16: =T16/S16 -> 0.014830653 | V16: =VLOOKUP($A16,TABEL,V$10,FALSE)/2+AA16/2 -> 30.95 | W16: =IF(V16="-","-",EXP(X16+1.645*Y16)) -> 33.072181 | X16: =IF(V16="-","-",LN(AA16)-Y16*Y16/2) -> 3.4655327 | Y16: =IF(V16="-","-",(SQRT(1.645^2+2*LN(AA16/V16))-1.645)) -> 0.020157893 | Z16: =IF(V16="-","-",EXP(X16)) -> 31.993499 | AA16: =VLOOKUP($A16,TABEL,AA$10,FALSE) -> 32 | AB16: =IF(V16="-","-",SQRT((EXP(Y16*Y16)-1)*EXP(2*X16+Y16*Y16))) -> 0.6451181 | AC16: =IF(V16="-","-",AB16/AA16) -> 0.020159941 | AD16: =VLOOKUP($A16,TABEL,AD$10,FALSE) -> - | AE16: =IF(AD16="-","-",EXP(AF16+1.645*AG16)) -> - | AF16: =IF(AD16="-","-",LN(AI16)-AG16*AG16/2) -> - | AG16: =IF(AD16="-","-",(SQRT(1.645^2+2*LN(AI16/AD16))-1.645)) -> - | AH16: =IF(AD16="-","-",EXP(AF16)) -> - | AI16: =VLOOKUP($A16,TABEL,AI$10,FALSE) -> - | AJ16: =IF(AD16="-","-",SQRT((EXP(AG16*AG16)-1)*EXP(2*AF16+AG16*AG16))) -> - | AK16: =IF(AD16="-","-",AJ16/AI16) -> - | AL16: =VLOOKUP($A16,TABEL,AL$10,FALSE) -> - | AM16: =IF(AL16="-","-",EXP(AN16+1.645*AO16)) -> - | AN16: =IF(AL16="-","-",LN(AQ16)-AO16*AO16/2) -> - | AO16: =IF(AL16="-","-",(SQRT(1.645^2+2*LN(AQ16/AL16))-1.645)) -> - | AP16: =IF(AL16="-","-",EXP(AN16)) -> - | AQ16: =VLOOKUP($A16,TABEL,AQ$10,FALSE) -> - | AR16: =IF(AL16="-","-",SQRT((EXP(AO16*AO16)-1)*EXP(2*AN16+AO16*AO16))) -> - | AS16: =IF(AL16="-","-",AR16/AQ16) -> - | AT16: =VLOOKUP($A16,TABEL,AT$10,FALSE) -> - | AU16: =IF(AT16="-","-",EXP(AV16+1.645*AW16)) -> - | AV16: =IF(AT16="-","-",LN(AY16)-AW16*AW16/2) -> - | AW16: =IF(AT16="-","-",(SQRT(1.645^2+2*LN(AY16/AT16))-1.645)) -> - | AX16: =IF(AT16="-","-",EXP(AV16)) -> - | AY16: =VLOOKUP($A16,TABEL,AY$10,FALSE) -> - | AZ16: =IF(AT16="-","-",SQRT((EXP(AW16*AW16)-1)*EXP(2*AV16+AW16*AW16))) -> - | BA16: =IF(AT16="-","-",AZ16/AY16) -> - | BB16: =VLOOKUP($A16,TABEL,BB$10,FALSE) -> - | BC16: =IF(BB16="-","-",EXP(BD16+1.645*BE16)) -> - | BD16: =IF(BB16="-","-",LN(BG16)-BE16*BE16/2) -> - | BE16: =IF(BB16="-","-",(SQRT(1.645^2+2*LN(BG16/BB16))-1.645)) -> - | BF16: =IF(BB16="-","-",EXP(BD16)) -> - | BG16: =BB16 -> - | BH16: =IF(BB16="-","-",SQRT((EXP(BE16*BE16)-1)*EXP(2*BD16+BE16*BE16))) -> - | BI16: =IF(BB16="-","-",BH16/BG16) -> - | BJ16: =VLOOKUP($A16,TABEL,BJ$10,FALSE) -> 103 | BK16: =VLOOKUP($A16,TABEL,BK$10,FALSE) -> 103 | BL16: =(LN(BK16)+LN(BJ16))/2 -> 4.634729 | BM16: =(LN(BK16)-LN(BJ16))/(2*1.645) -> 0 | BN16: =IF(BJ16="-","-",EXP(BL16)) -> 103 | BO16: =EXP(BL16+BM16*BM16/2) -> 103 | BP16: =SQRT((EXP(BM16*BM16)-1)*EXP(2*BL16+BM16*BM16)) -> 0 | BQ16: =BP16/BO16 -> 0
A17: H_Mr_kz_k | B17: SILTY_CLAY | E17: =VLOOKUP(A17,Kleurtabel!$A$2:$F$822,6,FALSE) -> #80008080 | F17: =VLOOKUP($A17,TABEL,F$10,FALSE) -> 15 | G17: =VLOOKUP($A17,TABEL,G$10,FALSE) -> 18 | H17: =(LN(G17)+LN(F17))/2 -> 2.799211 | I17: =(LN(G17)-LN(F17))/(2*1.645) -> 0.055416887 | J17: =IF(F17="-","-",EXP(H17)) -> 16.431677 | K17: =EXP(H17+I17*I17/2) -> 16.456927 | L17: =SQRT((EXP(I17*I17)-1)*EXP(2*H17+I17*I17)) -> 0.9126923 | M17: =L17/K17 -> 0.055459461 | N17: =VLOOKUP($A17,TABEL,N$10,FALSE) -> 15 | O17: =VLOOKUP($A17,TABEL,O$10,FALSE) -> 18 | P17: =(LN(O17)+LN(N17))/2 -> 2.799211 | Q17: =(LN(O17)-LN(N17))/(2*1.645) -> 0.055416887 | R17: =EXP(P17) -> 16.431677 | S17: =EXP(P17+Q17*Q17/2) -> 16.456927 | T17: =SQRT((EXP(Q17*Q17)-1)*EXP(2*P17+Q17*Q17)) -> 0.9126923 | U17: =T17/S17 -> 0.055459461 | V17: =VLOOKUP($A17,TABEL,V$10,FALSE)/2+AA17/2 -> 30.95 | W17: =IF(V17="-","-",EXP(X17+1.645*Y17)) -> 33.072181 | X17: =IF(V17="-","-",LN(AA17)-Y17*Y17/2) -> 3.4655327 | Y17: =IF(V17="-","-",(SQRT(1.645^2+2*LN(AA17/V17))-1.645)) -> 0.020157893 | Z17: =IF(V17="-","-",EXP(X17)) -> 31.993499 | AA17: =VLOOKUP($A17,TABEL,AA$10,FALSE) -> 32 | AB17: =IF(V17="-","-",SQRT((EXP(Y17*Y17)-1)*EXP(2*X17+Y17*Y17))) -> 0.6451181 | AC17: =IF(V17="-","-",AB17/AA17) -> 0.020159941 | AD17: =VLOOKUP($A17,TABEL,AD$10,FALSE) -> 0.259 | AE17: =IF(AD17="-","-",EXP(AF17+1.645*AG17)) -> 0.26502181 | AF17: =IF(AD17="-","-",LN(AI17)-AG17*AG17/2) -> -1.3394352 | AG17: =IF(AD17="-","-",(SQRT(1.645^2+2*LN(AI17/AD17))-1.645)) -> 0.0069860424 | AH17: =IF(AD17="-","-",EXP(AF17)) -> 0.26199361 | AI17: =VLOOKUP($A17,TABEL,AI$10,FALSE) -> 0.262 | AJ17: =IF(AD17="-","-",SQRT((EXP(AG17*AG17)-1)*EXP(2*AF17+AG17*AG17))) -> 0.0018303654 | AK17: =IF(AD17="-","-",AJ17/AI17) -> 0.0069861276 | AL17: =VLOOKUP($A17,TABEL,AL$10,FALSE) -> 0.892 | AM17: =IF(AL17="-","-",EXP(AN17+1.645*AO17)) -> 0.90804509 | AN17: =IF(AL17="-","-",LN(AQ17)-AO17*AO17/2) -> -0.1053752 | AO17: =IF(AL17="-","-",(SQRT(1.645^2+2*LN(AQ17/AL17))-1.645)) -> 0.005418814 | AP17: =IF(AL17="-","-",EXP(AN17)) -> 0.89998679 | AQ17: =VLOOKUP($A17,TABEL,AQ$10,FALSE) -> 0.9 | AR17: =IF(AL17="-","-",SQRT((EXP(AO17*AO17)-1)*EXP(2*AN17+AO17*AO17))) -> 0.0048769684 | AS17: =IF(AL17="-","-",AR17/AQ17) -> 0.0054188537 | AT17: =VLOOKUP($A17,TABEL,AT$10,FALSE) -> 28.42 | AU17: =IF(AT17="-","-",EXP(AV17+1.645*AW17)) -> 75.763975 | AV17: =IF(AT17="-","-",LN(AY17)-AW17*AW17/2) -> 3.837358 | AW17: =IF(AT17="-","-",(SQRT(1.645^2+2*LN(AY17/AT17))-1.645)) -> 0.29803337 | AX17: =IF(AT17="-","-",EXP(AV17)) -> 46.402717 | AY17: =VLOOKUP($A17,TABEL,AY$10,FALSE) -> 48.51 | AZ17: =IF(AT17="-","-",SQRT((EXP(AW17*AW17)-1)*EXP(2*AV17+AW17*AW17))) -> 14.784665 | BA17: =IF(AT17="-","-",AZ17/AY17) -> 0.30477561 | BB17: =VLOOKUP($A17,TABEL,BB$10,FALSE) -> 8 | BC17: =IF(BB17="-","-",EXP(BD17+1.645*BE17)) -> 8 | BD17: =IF(BB17="-","-",LN(BG17)-BE17*BE17/2) -> 2.0794415 | BE17: =IF(BB17="-","-",(SQRT(1.645^2+2*LN(BG17/BB17))-1.645)) -> 0 | BF17: =IF(BB17="-","-",EXP(BD17)) -> 8 | BG17: =BB17 -> 8 | BH17: =IF(BB17="-","-",SQRT((EXP(BE17*BE17)-1)*EXP(2*BD17+BE17*BE17))) -> 0 | BI17: =IF(BB17="-","-",BH17/BG17) -> 0 | BJ17: =VLOOKUP($A17,TABEL,BJ$10,FALSE) -> 60 | BK17: =VLOOKUP($A17,TABEL,BK$10,FALSE) -> 100 | BL17: =(LN(BK17)+LN(BJ17))/2 -> 4.3497574 | BM17: =(LN(BK17)-LN(BJ17))/(2*1.645) -> 0.15526615 | BN17: =IF(BJ17="-","-",EXP(BL17)) -> 77.459667 | BO17: =EXP(BL17+BM17*BM17/2) -> 78.398999 | BP17: =SQRT((EXP(BM17*BM17)-1)*EXP(2*BL17+BM17*BM17)) -> 12.246444 | BQ17: =BP17/BO17 -> 0.15620664
A18: H_Mkw_z&k | B18: SILTY_CLAY | E18: =VLOOKUP(A18,Kleurtabel!$A$2:$F$822,6,FALSE) -> #8099CC00 | F18: =VLOOKUP($A18,TABEL,F$10,FALSE) -> 15 | G18: =VLOOKUP($A18,TABEL,G$10,FALSE) -> 18 | H18: =(LN(G18)+LN(F18))/2 -> 2.799211 | I18: =(LN(G18)-LN(F18))/(2*1.645) -> 0.055416887 | J18: =IF(F18="-","-",EXP(H18)) -> 16.431677 | K18: =EXP(H18+I18*I18/2) -> 16.456927 | L18: =SQRT((EXP(I18*I18)-1)*EXP(2*H18+I18*I18)) -> 0.9126923 | M18: =L18/K18 -> 0.055459461 | N18: =VLOOKUP($A18,TABEL,N$10,FALSE) -> 15 | O18: =VLOOKUP($A18,TABEL,O$10,FALSE) -> 18 | P18: =(LN(O18)+LN(N18))/2 -> 2.799211 | Q18: =(LN(O18)-LN(N18))/(2*1.645) -> 0.055416887 | R18: =EXP(P18) -> 16.431677 | S18: =EXP(P18+Q18*Q18/2) -> 16.456927 | T18: =SQRT((EXP(Q18*Q18)-1)*EXP(2*P18+Q18*Q18)) -> 0.9126923 | U18: =T18/S18 -> 0.055459461 | V18: =VLOOKUP($A18,TABEL,V$10,FALSE)/2+AA18/2 -> 30.95 | W18: =IF(V18="-","-",EXP(X18+1.645*Y18)) -> 33.072181 | X18: =IF(V18="-","-",LN(AA18)-Y18*Y18/2) -> 3.4655327 | Y18: =IF(V18="-","-",(SQRT(1.645^2+2*LN(AA18/V18))-1.645)) -> 0.020157893 | Z18: =IF(V18="-","-",EXP(X18)) -> 31.993499 | AA18: =VLOOKUP($A18,TABEL,AA$10,FALSE) -> 32 | AB18: =IF(V18="-","-",SQRT((EXP(Y18*Y18)-1)*EXP(2*X18+Y18*Y18))) -> 0.6451181 | AC18: =IF(V18="-","-",AB18/AA18) -> 0.020159941 | AD18: =VLOOKUP($A18,TABEL,AD$10,FALSE) -> 0.259 | AE18: =IF(AD18="-","-",EXP(AF18+1.645*AG18)) -> 0.26502181 | AF18: =IF(AD18="-","-",LN(AI18)-AG18*AG18/2) -> -1.3394352 | AG18: =IF(AD18="-","-",(SQRT(1.645^2+2*LN(AI18/AD18))-1.645)) -> 0.0069860424 | AH18: =IF(AD18="-","-",EXP(AF18)) -> 0.26199361 | AI18: =VLOOKUP($A18,TABEL,AI$10,FALSE) -> 0.262 | AJ18: =IF(AD18="-","-",SQRT((EXP(AG18*AG18)-1)*EXP(2*AF18+AG18*AG18))) -> 0.0018303654 | AK18: =IF(AD18="-","-",AJ18/AI18) -> 0.0069861276 | AL18: =VLOOKUP($A18,TABEL,AL$10,FALSE) -> 0.892 | AM18: =IF(AL18="-","-",EXP(AN18+1.645*AO18)) -> 0.90804509 | AN18: =IF(AL18="-","-",LN(AQ18)-AO18*AO18/2) -> -0.1053752 | AO18: =IF(AL18="-","-",(SQRT(1.645^2+2*LN(AQ18/AL18))-1.645)) -> 0.005418814 | AP18: =IF(AL18="-","-",EXP(AN18)) -> 0.89998679 | AQ18: =VLOOKUP($A18,TABEL,AQ$10,FALSE) -> 0.9 | AR18: =IF(AL18="-","-",SQRT((EXP(AO18*AO18)-1)*EXP(2*AN18+AO18*AO18))) -> 0.0048769684 | AS18: =IF(AL18="-","-",AR18/AQ18) -> 0.0054188537 | AT18: =VLOOKUP($A18,TABEL,AT$10,FALSE) -> 28.42 | AU18: =IF(AT18="-","-",EXP(AV18+1.645*AW18)) -> 75.763975 | AV18: =IF(AT18="-","-",LN(AY18)-AW18*AW18/2) -> 3.837358 | AW18: =IF(AT18="-","-",(SQRT(1.645^2+2*LN(AY18/AT18))-1.645)) -> 0.29803337 | AX18: =IF(AT18="-","-",EXP(AV18)) -> 46.402717 | AY18: =VLOOKUP($A18,TABEL,AY$10,FALSE) -> 48.51 | AZ18: =IF(AT18="-","-",SQRT((EXP(AW18*AW18)-1)*EXP(2*AV18+AW18*AW18))) -> 14.784665 | BA18: =IF(AT18="-","-",AZ18/AY18) -> 0.30477561 | BB18: =VLOOKUP($A18,TABEL,BB$10,FALSE) -> 8 | BC18: =IF(BB18="-","-",EXP(BD18+1.645*BE18)) -> 8 | BD18: =IF(BB18="-","-",LN(BG18)-BE18*BE18/2) -> 2.0794415 | BE18: =IF(BB18="-","-",(SQRT(1.645^2+2*LN(BG18/BB18))-1.645)) -> 0 | BF18: =IF(BB18="-","-",EXP(BD18)) -> 8 | BG18: =BB18 -> 8 | BH18: =IF(BB18="-","-",SQRT((EXP(BE18*BE18)-1)*EXP(2*BD18+BE18*BE18))) -> 0 | BI18: =IF(BB18="-","-",BH18/BG18) -> 0 | BJ18: =VLOOKUP($A18,TABEL,BJ$10,FALSE) -> 60 | BK18: =VLOOKUP($A18,TABEL,BK$10,FALSE) -> 100 | BL18: =(LN(BK18)+LN(BJ18))/2 -> 4.3497574 | BM18: =(LN(BK18)-LN(BJ18))/(2*1.645) -> 0.15526615 | BN18: =IF(BJ18="-","-",EXP(BL18)) -> 77.459667 | BO18: =EXP(BL18+BM18*BM18/2) -> 78.398999 | BP18: =SQRT((EXP(BM18*BM18)-1)*EXP(2*BL18+BM18*BM18)) -> 12.246444 | BQ18: =BP18/BO18 -> 0.15620664
A19: H_Mkw_z_k | B19: SILTY_CLAY | E19: =VLOOKUP(A19,Kleurtabel!$A$2:$F$822,6,FALSE) -> #N/A | F19: =F18 -> 15 | G19: =G18 -> 18 | H19: =H18 -> 2.799211 | I19: =I18 -> 0.055416887 | J19: =J18 -> 16.431677 | K19: =K18 -> 16.456927 | L19: =L18 -> 0.9126923 | M19: =M18 -> 0.055459461 | ... BQ19: =BQ18 -> 0.15620664
A20: H_Mp_k | B20: CLAY_ORGANIC | E20: =VLOOKUP(A20,Kleurtabel!$A$2:$F$822,6,FALSE) -> #80008080 | F20: =VLOOKUP($A20,TABEL,F$10,FALSE) -> 15 | G20: =VLOOKUP($A20,TABEL,G$10,FALSE) -> 18 | H20: =(LN(G20)+LN(F20))/2 -> 2.799211 | I20: =(LN(G20)-LN(F20))/(2*1.645) -> 0.055416887 | J20: =IF(F20="-","-",EXP(H20)) -> 16.431677 | K20: =EXP(H20+I20*I20/2) -> 16.456927 | L20: =SQRT((EXP(I20*I20)-1)*EXP(2*H20+I20*I20)) -> 0.9126923 | M20: =L20/K20 -> 0.055459461 | N20: =VLOOKUP($A20,TABEL,N$10,FALSE) -> 15 | O20: =VLOOKUP($A20,TABEL,O$10,FALSE) -> 18 | P20: =(LN(O20)+LN(N20))/2 -> 2.799211 | Q20: =(LN(O20)-LN(N20))/(2*1.645) -> 0.055416887 | R20: =EXP(P20) -> 16.431677 | S20: =EXP(P20+Q20*Q20/2) -> 16.456927 | T20: =SQRT((EXP(Q20*Q20)-1)*EXP(2*P20+Q20*Q20)) -> 0.9126923 | U20: =T20/S20 -> 0.055459461 | V20: =VLOOKUP($A20,TABEL,V$10,FALSE)/2+AA20/2 -> 38 | W20: =IF(V20="-","-",EXP(X20+1.645*Y20)) -> 46.255591 | X20: =IF(V20="-","-",LN(AA20)-Y20*Y20/2) -> 3.7358842 | Y20: =IF(V20="-","-",(SQRT(1.645^2+2*LN(AA20/V20))-1.645)) -> 0.059755677 | Z20: =IF(V20="-","-",EXP(X20)) -> 41.925081 | AA20: =VLOOKUP($A20,TABEL,AA$10,FALSE) -> 42 | AB20: =IF(V20="-","-",SQRT((EXP(Y20*Y20)-1)*EXP(2*X20+Y20*Y20))) -> 2.5119805 | AC20: =IF(V20="-","-",AB20/AA20) -> 0.059809059 | AD20: =VLOOKUP($A20,TABEL,AD$10,FALSE) -> 0.281 | AE20: =IF(AD20="-","-",EXP(AF20+1.645*AG20)) -> 0.29917961 | AF20: =IF(AD20="-","-",LN(AI20)-AG20*AG20/2) -> -1.2380559 | AG20: =IF(AD20="-","-",(SQRT(1.645^2+2*LN(AI20/AD20))-1.645)) -> 0.019054539 | AH20: =IF(AD20="-","-",EXP(AF20)) -> 0.28994736 | AI20: =VLOOKUP($A20,TABEL,AI$10,FALSE) -> 0.29 | AJ20: =IF(AD20="-","-",SQRT((EXP(AG20*AG20)-1)*EXP(2*AF20+AG20*AG20))) -> 0.0055263178 | AK20: =IF(AD20="-","-",AJ20/AI20) -> 0.019056268 | AL20: =VLOOKUP($A20,TABEL,AL$10,FALSE) -> 0.892 | AM20: =IF(AL20="-","-",EXP(AN20+1.645*AO20)) -> 0.90804509 | AN20: =IF(AL20="-","-",LN(AQ20)-AO20*AO20/2) -> -0.1053752 | AO20: =IF(AL20="-","-",(SQRT(1.645^2+2*LN(AQ20/AL20))-1.645)) -> 0.005418814 | AP20: =IF(AL20="-","-",EXP(AN20)) -> 0.89998679 | AQ20: =VLOOKUP($A20,TABEL,AQ$10,FALSE) -> 0.9 | AR20: =IF(AL20="-","-",SQRT((EXP(AO20*AO20)-1)*EXP(2*AN20+AO20*AO20))) -> 0.0048769684 | AS20: =IF(AL20="-","-",AR20/AQ20) -> 0.0054188537 | AT20: =VLOOKUP($A20,TABEL,AT$10,FALSE) -> 11.57 | AU20: =IF(AT20="-","-",EXP(AV20+1.645*AW20)) -> 36.715039 | AV20: =IF(AT20="-","-",LN(AY20)-AW20*AW20/2) -> 3.025801 | AW20: =IF(AT20="-","-",(SQRT(1.645^2+2*LN(AY20/AT20))-1.645)) -> 0.3509942 | AX20: =IF(AT20="-","-",EXP(AV20)) -> 20.610507 | AY20: =VLOOKUP($A20,TABEL,AY$10,FALSE) -> 21.92 | AZ20: =IF(AT20="-","-",SQRT((EXP(AW20*AW20)-1)*EXP(2*AV20+AW20*AW20))) -> 7.9369516 | BA20: =IF(AT20="-","-",AZ20/AY20) -> 0.36208721 | BB20: =VLOOKUP($A20,TABEL,BB$10,FALSE) -> 8 | BC20: =IF(BB20="-","-",EXP(BD20+1.645*BE20)) -> 8 | BD20: =IF(BB20="-","-",LN(BG20)-BE20*BE20/2) -> 2.0794415 | BE20: =IF(BB20="-","-",(SQRT(1.645^2+2*LN(BG20/BB20))-1.645)) -> 0 | BF20: =IF(BB20="-","-",EXP(BD20)) -> 8 | BG20: =BB20 -> 8 | BH20: =IF(BB20="-","-",SQRT((EXP(BE20*BE20)-1)*EXP(2*BD20+BE20*BE20))) -> 0 | BI20: =IF(BB20="-","-",BH20/BG20) -> 0 | BJ20: =VLOOKUP($A20,TABEL,BJ$10,FALSE) -> 60 | BK20: =VLOOKUP($A20,TABEL,BK$10,FALSE) -> 100 | BL20: =(LN(BK20)+LN(BJ20))/2 -> 4.3497574 | BM20: =(LN(BK20)-LN(BJ20))/(2*1.645) -> 0.15526615 | BN20: =IF(BJ20="-","-",EXP(BL20)) -> 77.459667 | BO20: =EXP(BL20+BM20*BM20/2) -> 78.398999 | BP20: =SQRT((EXP(BM20*BM20)-1)*EXP(2*BL20+BM20*BM20)) -> 12.246444 | BQ20: =BP20/BO20 -> 0.15620664
A21: H_Mp_ko | B21: CLAY_ORGANIC | E21: =VLOOKUP(A21,Kleurtabel!$A$2:$F$822,6,FALSE) -> #80297551 | F21: =VLOOKUP($A21,TABEL,F$10,FALSE) -> 13 | G21: =VLOOKUP($A21,TABEL,G$10,FALSE) -> 15 | H21: =(LN(G21)+LN(F21))/2 -> 2.6364998 | I21: =(LN(G21)-LN(F21))/(2*1.645) -> 0.043495697 | J21: =IF(F21="-","-",EXP(H21)) -> 13.96424 | K21: =EXP(H21+I21*I21/2) -> 13.977456 | L21: =SQRT((EXP(I21*I21)-1)*EXP(2*H21+I21*I21)) -> 0.60824683 | M21: =L21/K21 -> 0.043516277 | N21: =VLOOKUP($A21,TABEL,N$10,FALSE) -> 13 | O21: =VLOOKUP($A21,TABEL,O$10,FALSE) -> 15 | P21: =(LN(O21)+LN(N21))/2 -> 2.6364998 | Q21: =(LN(O21)-LN(N21))/(2*1.645) -> 0.043495697 | R21: =EXP(P21) -> 13.96424 | S21: =EXP(P21+Q21*Q21/2) -> 13.977456 | T21: =SQRT((EXP(Q21*Q21)-1)*EXP(2*P21+Q21*Q21)) -> 0.60824683 | U21: =T21/S21 -> 0.043516277 | V21: =VLOOKUP($A21,TABEL,V$10,FALSE)/2+AA21/2 -> 41 | W21: =IF(V21="-","-",EXP(X21+1.645*Y21)) -> 51.36799 | X21: =IF(V21="-","-",LN(AA21)-Y21*Y21/2) -> 3.8262936 | Y21: =IF(V21="-","-",(SQRT(1.645^2+2*LN(AA21/V21))-1.645)) -> 0.068523755 | Z21: =IF(V21="-","-",EXP(X21)) -> 45.89213 | AA21: =VLOOKUP($A21,TABEL,AA$10,FALSE) -> 46 | AB21: =IF(V21="-","-",SQRT((EXP(Y21*Y21)-1)*EXP(2*X21+Y21*Y21))) -> 3.1557965 | AC21: =IF(V21="-","-",AB21/AA21) -> 0.068604272 | AD21: =VLOOKUP($A21,TABEL,AD$10,FALSE) -> 0.306 | AE21: =IF(AD21="-","-",EXP(AF21+1.645*AG21)) -> 0.32416509 | AF21: =IF(AD21="-","-",LN(AI21)-AG21*AG21/2) -> -1.1553363 | AG21: =IF(AD21="-","-",(SQRT(1.645^2+2*LN(AI21/AD21))-1.645)) -> 0.017528217 | AH21: =IF(AD21="-","-",EXP(AF21)) -> 0.31495161 | AI21: =VLOOKUP($A21,TABEL,AI$10,FALSE) -> 0.315 | AJ21: =IF(AD21="-","-",SQRT((EXP(AG21*AG21)-1)*EXP(2*AF21+AG21*AG21))) -> 0.0055218126 | AK21: =IF(AD21="-","-",AJ21/AI21) -> 0.017529564 | AL21: =VLOOKUP($A21,TABEL,AL$10,FALSE) -> 0.891 | AM21: =IF(AL21="-","-",EXP(AN21+1.645*AO21)) -> 0.9090571 | AN21: =IF(AL21="-","-",LN(AQ21)-AO21*AO21/2) -> -0.10537911 | AO21: =IF(AL21="-","-",(SQRT(1.645^2+2*LN(AQ21/AL21))-1.645)) -> 0.0060983228 | AP21: =IF(AL21="-","-",EXP(AN21)) -> 0.89998326 | AQ21: =VLOOKUP($A21,TABEL,AQ$10,FALSE) -> 0.9 | AR21: =IF(AL21="-","-",SQRT((EXP(AO21*AO21)-1)*EXP(2*AN21+AO21*AO21))) -> 0.0054885416 | AS21: =IF(AL21="-","-",AR21/AQ21) -> 0.0060983795 | AT21: =VLOOKUP($A21,TABEL,AT$10,FALSE) -> 5.67 | AU21: =IF(AT21="-","-",EXP(AV21+1.645*AW21)) -> 38.585736 | AV21: =IF(AT21="-","-",LN(AY21)-AW21*AW21/2) -> 2.6940359 | AW21: =IF(AT21="-","-",(SQRT(1.645^2+2*LN(AY21/AT21))-1.645)) -> 0.58288558 | AX21: =IF(AT21="-","-",EXP(AV21)) -> 14.791252 | AY21: =VLOOKUP($A21,TABEL,AY$10,FALSE) -> 17.53 | AZ21: =IF(AT21="-","-",SQRT((EXP(AW21*AW21)-1)*EXP(2*AV21+AW21*AW21))) -> 11.150572 | BA21: =IF(AT21="-","-",AZ21/AY21) -> 0.63608511 | BB21: =VLOOKUP($A21,TABEL,BB$10,FALSE) -> 4.1 | BC21: =IF(BB21="-","-",EXP(BD21+1.645*BE21)) -> 4.1 | BD21: =IF(BB21="-","-",LN(BG21)-BE21*BE21/2) -> 1.410987 | BE21: =IF(BB21="-","-",(SQRT(1.645^2+2*LN(BG21/BB21))-1.645)) -> 0 | BF21: =IF(BB21="-","-",EXP(BD21)) -> 4.1 | BG21: =BB21 -> 4.1 | BH21: =IF(BB21="-","-",SQRT((EXP(BE21*BE21)-1)*EXP(2*BD21+BE21*BE21))) -> 0 | BI21: =IF(BB21="-","-",BH21/BG21) -> 0 | BJ21: =VLOOKUP($A21,TABEL,BJ$10,FALSE) -> 60 | BK21: =VLOOKUP($A21,TABEL,BK$10,FALSE) -> 100 | BL21: =(LN(BK21)+LN(BJ21))/2 -> 4.3497574 | BM21: =(LN(BK21)-LN(BJ21))/(2*1.645) -> 0.15526615 | BN21: =IF(BJ21="-","-",EXP(BL21)) -> 77.459667 | BO21: =EXP(BL21+BM21*BM21/2) -> 78.398999 | BP21: =SQRT((EXP(BM21*BM21)-1)*EXP(2*BL21+BM21*BM21)) -> 12.246444 | BQ21: =BP21/BO21 -> 0.15620664
A22: H_Ml_ko | B22: CLAY_ORGANIC | E22: =VLOOKUP(A22,Kleurtabel!$A$2:$F$822,6,FALSE) -> #80006F6C | F22: =VLOOKUP($A22,TABEL,F$10,FALSE) -> 13 | G22: =VLOOKUP($A22,TABEL,G$10,FALSE) -> 15 | H22: =(LN(G22)+LN(F22))/2 -> 2.6364998 | I22: =(LN(G22)-LN(F22))/(2*1.645) -> 0.043495697 | J22: =IF(F22="-","-",EXP(H22)) -> 13.96424 | K22: =EXP(H22+I22*I22/2) -> 13.977456 | L22: =SQRT((EXP(I22*I22)-1)*EXP(2*H22+I22*I22)) -> 0.60824683 | M22: =L22/K22 -> 0.043516277 | N22: =VLOOKUP($A22,TABEL,N$10,FALSE) -> 13 | O22: =VLOOKUP($A22,TABEL,O$10,FALSE) -> 15 | P22: =(LN(O22)+LN(N22))/2 -> 2.6364998 | Q22: =(LN(O22)-LN(N22))/(2*1.645) -> 0.043495697 | R22: =EXP(P22) -> 13.96424 | S22: =EXP(P22+Q22*Q22/2) -> 13.977456 | T22: =SQRT((EXP(Q22*Q22)-1)*EXP(2*P22+Q22*Q22)) -> 0.60824683 | U22: =T22/S22 -> 0.043516277 | V22: =VLOOKUP($A22,TABEL,V$10,FALSE)/2+AA22/2 -> 41 | W22: =IF(V22="-","-",EXP(X22+1.645*Y22)) -> 51.36799 | X22: =IF(V22="-","-",LN(AA22)-Y22*Y22/2) -> 3.8262936 | Y22: =IF(V22="-","-",(SQRT(1.645^2+2*LN(AA22/V22))-1.645)) -> 0.068523755 | Z22: =IF(V22="-","-",EXP(X22)) -> 45.89213 | AA22: =VLOOKUP($A22,TABEL,AA$10,FALSE) -> 46 | AB22: =IF(V22="-","-",SQRT((EXP(Y22*Y22)-1)*EXP(2*X22+Y22*Y22))) -> 3.1557965 | AC22: =IF(V22="-","-",AB22/AA22) -> 0.068604272 | AD22: =VLOOKUP($A22,TABEL,AD$10,FALSE) -> 0.306 | AE22: =IF(AD22="-","-",EXP(AF22+1.645*AG22)) -> 0.32416509 | AF22: =IF(AD22="-","-",LN(AI22)-AG22*AG22/2) -> -1.1553363 | AG22: =IF(AD22="-","-",(SQRT(1.645^2+2*LN(AI22/AD22))-1.645)) -> 0.017528217 | AH22: =IF(AD22="-","-",EXP(AF22)) -> 0.31495161 | AI22: =VLOOKUP($A22,TABEL,AI$10,FALSE) -> 0.315 | AJ22: =IF(AD22="-","-",SQRT((EXP(AG22*AG22)-1)*EXP(2*AF22+AG22*AG22))) -> 0.0055218126 | AK22: =IF(AD22="-","-",AJ22/AI22) -> 0.017529564 | AL22: =VLOOKUP($A22,TABEL,AL$10,FALSE) -> 0.891 | AM22: =IF(AL22="-","-",EXP(AN22+1.645*AO22)) -> 0.9090571 | AN22: =IF(AL22="-","-",LN(AQ22)-AO22*AO22/2) -> -0.10537911 | AO22: =IF(AL22="-","-",(SQRT(1.645^2+2*LN(AQ22/AL22))-1.645)) -> 0.0060983228 | AP22: =IF(AL22="-","-",EXP(AN22)) -> 0.89998326 | AQ22: =VLOOKUP($A22,TABEL,AQ$10,FALSE) -> 0.9 | AR22: =IF(AL22="-","-",SQRT((EXP(AO22*AO22)-1)*EXP(2*AN22+AO22*AO22))) -> 0.0054885416 | AS22: =IF(AL22="-","-",AR22/AQ22) -> 0.0060983795 | AT22: =VLOOKUP($A22,TABEL,AT$10,FALSE) -> 5.67 | AU22: =IF(AT22="-","-",EXP(AV22+1.645*AW22)) -> 38.585736 | AV22: =IF(AT22="-","-",LN(AY22)-AW22*AW22/2) -> 2.6940359 | AW22: =IF(AT22="-","-",(SQRT(1.645^2+2*LN(AY22/AT22))-1.645)) -> 0.58288558 | AX22: =IF(AT22="-","-",EXP(AV22)) -> 14.791252 | AY22: =VLOOKUP($A22,TABEL,AY$10,FALSE) -> 17.53 | AZ22: =IF(AT22="-","-",SQRT((EXP(AW22*AW22)-1)*EXP(2*AV22+AW22*AW22))) -> 11.150572 | BA22: =IF(AT22="-","-",AZ22/AY22) -> 0.63608511 | BB22: =VLOOKUP($A22,TABEL,BB$10,FALSE) -> 4.1 | BC22: =IF(BB22="-","-",EXP(BD22+1.645*BE22)) -> 4.1 | BD22: =IF(BB22="-","-",LN(BG22)-BE22*BE22/2) -> 1.410987 | BE22: =IF(BB22="-","-",(SQRT(1.645^2+2*LN(BG22/BB22))-1.645)) -> 0 | BF22: =IF(BB22="-","-",EXP(BD22)) -> 4.1 | BG22: =BB22 -> 4.1 | BH22: =IF(BB22="-","-",SQRT((EXP(BE22*BE22)-1)*EXP(2*BD22+BE22*BE22))) -> 0 | BI22: =IF(BB22="-","-",BH22/BG22) -> 0 | BJ22: =VLOOKUP($A22,TABEL,BJ$10,FALSE) -> 60 | BK22: =VLOOKUP($A22,TABEL,BK$10,FALSE) -> 100 | BL22: =(LN(BK22)+LN(BJ22))/2 -> 4.3497574 | BM22: =(LN(BK22)-LN(BJ22))/(2*1.645) -> 0.15526615 | BN22: =IF(BJ22="-","-",EXP(BL22)) -> 77.459667 | BO22: =EXP(BL22+BM22*BM22/2) -> 78.398999 | BP22: =SQRT((EXP(BM22*BM22)-1)*EXP(2*BL22+BM22*BM22)) -> 12.246444 | BQ22: =BP22/BO22 -> 0.15620664
